<?xml version="1.0" ?>
<!-- =================================================================================== -->
<!-- |    This document was autogenerated by xacro from cet200.xacro -->
<!-- |    EDITING THIS FILE BY HAND IS NOT RECOMMENDED                                 | -->
<!-- =================================================================================== -->
<robot name="cet200">
  <!-- ================================================================ -->
  <!-- ================================================================ -->
  <!-- Links, Joints -->
  <link name="TF_Origin"/>
  <link name="base_link"/>
  <joint name="Dummy_LockJoint_Origin" type="fixed">
    <parent link="TF_Origin"/>
    <child link="RB_TrackFrame"/>
  </joint>
  <link name="RB_TrackFrame">
    <inertial>
      <mass value="3800"/>
      <origin rpy="0 0 0" xyz="0.05201620740931711 1.0183557399152014e-06 0.5308690686271093"/>
      <inertia ixx="2862.58" ixy="-0.00237404" ixz="2.47481e-05" iyy="2290.29" iyz="34.9716" izz="4857.89"/>
    </inertial>
    <visual>
      <geometry>
        <mesh filename="package://cet200_description/meshes/track_frame.dae"/>
      </geometry>
    </visual>
  </link>
  <!-- Handle base_link as a dummy link. ObserverFrame in AGX -->
  <joint name="Dummy_LockJoint_RB_TrackFrame_base" type="fixed">
    <parent link="RB_TrackFrame"/>
    <child link="base_link"/>
  </joint>
  <joint name="Hinge_Slew" type="continuous">
    <origin rpy="0 0 0" xyz="0 0 1"/>
    <axis xyz="0 0 1"/>
    <parent link="RB_TrackFrame"/>
    <child link="RB_UpperStructure"/>
    <limit effort="70000" velocity="1.256637061"/>
  </joint>
  <link name="RB_UpperStructure">
    <inertial>
      <mass value="7600"/>
      <origin rpy="0 0 0" xyz="-1.9067453625871538 3.5826687072582075e-07 0.5699960477872861"/>
      <inertia ixx="6075.62" ixy="-1585.64" ixz="-1044.18" iyy="9686.21" iyz="-412.978" izz="13711.7"/>
    </inertial>
    <visual>
      <geometry>
        <mesh filename="package://cet200_description/meshes/upper_structure.dae"/>
      </geometry>
    </visual>
  </link>
  <joint name="Hinge_Boom" type="revolute">
    <origin rpy="0 0 0" xyz="0.18 0 0.83"/>
    <axis xyz="0 1 0"/>
    <parent link="RB_UpperStructure"/>
    <child link="RB_Boom"/>
    <limit effort="2009946.205" lower="-0.443" upper="1.127" velocity="0.648409027"/>
  </joint>
  <link name="RB_Boom">
    <inertial>
      <mass value="1440"/>
      <origin rpy="0 0 0" xyz="1.892940763973838 8.147612283200667e-05 2.0891289253932284"/>
      <inertia ixx="956.006" ixy="1259.54" ixz="-0.139389" iyy="2328.5" iyz="0.0825067" izz="2913.61"/>
    </inertial>
    <visual>
      <geometry>
        <mesh filename="package://cet200_description/meshes/boom.dae"/>
      </geometry>
    </visual>
  </link>
  <joint name="Hinge_Arm" type="revolute">
    <origin rpy="0 0 0" xyz="4.71397 0 3.19445"/>
    <axis xyz="0 1 0"/>
    <parent link="RB_Boom"/>
    <child link="RB_Arm"/>
    <limit effort="300268.1523" lower="-1.40" upper="0.648" velocity="0.59757376"/>
  </joint>
  <link name="RB_Arm">
    <inertial>
      <mass value="950"/>
      <origin rpy="0 0 0" xyz="0.12784681679964738 5.671064185895034e-07 -0.9585825418396574"/>
      <inertia ixx="818.209" ixy="-45.9014" ixz="-0.00018497" iyy="24.3643" iyz="-0.00325513" izz="809.144"/>
    </inertial>
    <visual>
      <geometry>
        <mesh filename="package://cet200_description/meshes/arm.dae"/>
      </geometry>
    </visual>
  </link>
  <joint name="Hinge_Bucket" type="revolute">
    <origin rpy="0 0 0" xyz="-0.0006 0 -2.9"/>
    <axis xyz="0 1 0"/>
    <parent link="RB_Arm"/>
    <child link="RB_Bucket"/>
    <limit effort="253122.1717" lower="-1.236" upper="1.77" velocity="0.706018147"/>
  </joint>
  <link name="RB_Bucket">
    <inertial>
      <mass value="700"/>
      <origin rpy="0 0 0" xyz="-0.01426160488025463 -2.7650072185771593e-06 -0.5611512049188314"/>
      <inertia ixx="199.455" ixy="-0.000719484" ixz="58.3155" iyy="187.447" iyz="-0.00111114" izz="165.43"/>
    </inertial>
    <visual>
      <geometry>
        <mesh filename="package://cet200_description/meshes/bucket.dae"/>
      </geometry>
    </visual>
    <collision>
      <geometry>
        <mesh filename="package://cet200_description/meshes/collider_bucket.stl"/>
      </geometry>
    </collision>
  </link>
  <joint name="Hinge_Sprocket_L" type="continuous">
    <origin rpy="0 0 0" xyz="-1.6872 1.1 0.38945"/>
    <axis xyz="0 1 0"/>
    <parent link="RB_TrackFrame"/>
    <child link="RB_Sprocket_L"/>
    <limit effort="38437" velocity="4.074104494"/>
  </joint>
  <link name="RB_Sprocket_L">
    <inertial>
      <mass value="340"/>
      <origin rpy="0 0 0" xyz="0.0009721884578390849 0.06961311938672243 -0.00024814935669242866"/>
      <inertia ixx="10.2047" ixy="-0.459781" ixz="2.23037e-10" iyy="6.83585" iyz="-2.9895e-11" izz="6.77422"/>
    </inertial>
    <visual>
      <origin rpy="0 0 0" xyz="0 0 0"/>
      <geometry>
        <mesh filename="package://cet200_description/meshes/sprocket.dae"/>
      </geometry>
    </visual>
    <collision>
      <origin rpy="1.5708 0 0" xyz="0 0 0"/>
      <geometry>
        <cylinder length="0.05" radius="0.24"/>
      </geometry>
    </collision>
  </link>
  <joint name="Hinge_Idler_L" type="continuous">
    <origin rpy="0 0 0" xyz="1.6872 1.1 0.38945"/>
    <axis xyz="0 1 0"/>
    <parent link="RB_TrackFrame"/>
    <child link="RB_Idler_L"/>
  </joint>
  <link name="RB_Idler_L">
    <inertial>
      <mass value="108"/>
      <origin rpy="0 0 0" xyz="0 0 0"/>
      <inertia ixx="2.34497" ixy="0" ixz="0" iyy="4.27217" iyz="4.22502e-06" izz="2.345"/>
    </inertial>
    <visual>
      <geometry>
        <mesh filename="package://cet200_description/meshes/idler.dae"/>
      </geometry>
    </visual>
    <collision>
      <origin rpy="1.5708 0 0" xyz="0 0 0"/>
      <geometry>
        <cylinder length="0.14" radius="0.24"/>
      </geometry>
    </collision>
  </link>
  <joint name="Hinge_Roller_L1" type="continuous">
    <origin rpy="0 0 0" xyz="0.55 1.1 0.71245"/>
    <axis xyz="0 1 0"/>
    <parent link="RB_TrackFrame"/>
    <child link="RB_Roller_L1"/>
  </joint>
  <link name="RB_Roller_L1">
    <inertial>
      <mass value="35"/>
      <origin rpy="0 0 0" xyz="0 0 0"/>
      <inertia ixx="0.181184" ixy="4.37227e-07" ixz="3.54717e-07" iyy="0.1057" iyz="0.0612396" izz="0.131501"/>
    </inertial>
    <visual>
      <geometry>
        <mesh filename="package://cet200_description/meshes/roller.dae"/>
      </geometry>
    </visual>
    <collision>
      <origin rpy="1.5708 0 0" xyz="0 0 0"/>
      <geometry>
        <cylinder length="0.2144" radius="0.048"/>
      </geometry>
    </collision>
  </link>
  <joint name="Hinge_Roller_L2" type="continuous">
    <origin rpy="0 0 0" xyz="-0.55 1.1 0.71245"/>
    <axis xyz="0 1 0"/>
    <parent link="RB_TrackFrame"/>
    <child link="RB_Roller_L2"/>
  </joint>
  <link name="RB_Roller_L2">
    <inertial>
      <mass value="35"/>
      <origin rpy="0 0 0" xyz="0 0 0"/>
      <inertia ixx="0.181184" ixy="4.37227e-07" ixz="3.54717e-07" iyy="0.1057" iyz="0.0612396" izz="0.131501"/>
    </inertial>
    <visual>
      <geometry>
        <mesh filename="package://cet200_description/meshes/roller.dae"/>
      </geometry>
    </visual>
    <collision>
      <origin rpy="1.5708 0 0" xyz="0 0 0"/>
      <geometry>
        <cylinder length="0.2144" radius="0.048"/>
      </geometry>
    </collision>
  </link>
  <joint name="Hinge_Roller_L3" type="continuous">
    <origin rpy="0 0 0" xyz="1.225 1.1 0.18295"/>
    <axis xyz="0 1 0"/>
    <parent link="RB_TrackFrame"/>
    <child link="RB_Roller_L3"/>
  </joint>
  <link name="RB_Roller_L3">
    <inertial>
      <mass value="35"/>
      <origin rpy="0 0 0" xyz="0 0 0"/>
      <inertia ixx="0.181184" ixy="4.37227e-07" ixz="3.54717e-07" iyy="0.1057" iyz="0.0612396" izz="0.131501"/>
    </inertial>
    <visual>
      <geometry>
        <mesh filename="package://cet200_description/meshes/roller.dae"/>
      </geometry>
    </visual>
    <collision>
      <origin rpy="1.5708 0 0" xyz="0 0 0"/>
      <geometry>
        <cylinder length="0.2144" radius="0.048"/>
      </geometry>
    </collision>
  </link>
  <joint name="Hinge_Roller_L4" type="continuous">
    <origin rpy="0 0 0" xyz="0.825 1.1 0.18295"/>
    <axis xyz="0 1 0"/>
    <parent link="RB_TrackFrame"/>
    <child link="RB_Roller_L4"/>
  </joint>
  <link name="RB_Roller_L4">
    <inertial>
      <mass value="35"/>
      <origin rpy="0 0 0" xyz="0 0 0"/>
      <inertia ixx="0.181184" ixy="4.37227e-07" ixz="3.54717e-07" iyy="0.1057" iyz="0.0612396" izz="0.131501"/>
    </inertial>
    <visual>
      <geometry>
        <mesh filename="package://cet200_description/meshes/roller.dae"/>
      </geometry>
    </visual>
    <collision>
      <origin rpy="1.5708 0 0" xyz="0 0 0"/>
      <geometry>
        <cylinder length="0.2144" radius="0.048"/>
      </geometry>
    </collision>
  </link>
  <joint name="Hinge_Roller_L5" type="continuous">
    <origin rpy="0 0 0" xyz="0.425 1.1 0.18295"/>
    <axis xyz="0 1 0"/>
    <parent link="RB_TrackFrame"/>
    <child link="RB_Roller_L5"/>
  </joint>
  <link name="RB_Roller_L5">
    <inertial>
      <mass value="35"/>
      <origin rpy="0 0 0" xyz="0 0 0"/>
      <inertia ixx="0.181184" ixy="4.37227e-07" ixz="3.54717e-07" iyy="0.1057" iyz="0.0612396" izz="0.131501"/>
    </inertial>
    <visual>
      <geometry>
        <mesh filename="package://cet200_description/meshes/roller.dae"/>
      </geometry>
    </visual>
    <collision>
      <origin rpy="1.5708 0 0" xyz="0 0 0"/>
      <geometry>
        <cylinder length="0.2144" radius="0.048"/>
      </geometry>
    </collision>
  </link>
  <joint name="Hinge_Roller_L6" type="continuous">
    <origin rpy="0 0 0" xyz="0.025 1.1 0.18295"/>
    <axis xyz="0 1 0"/>
    <parent link="RB_TrackFrame"/>
    <child link="RB_Roller_L6"/>
  </joint>
  <link name="RB_Roller_L6">
    <inertial>
      <mass value="35"/>
      <origin rpy="0 0 0" xyz="0 0 0"/>
      <inertia ixx="0.181184" ixy="4.37227e-07" ixz="3.54717e-07" iyy="0.1057" iyz="0.0612396" izz="0.131501"/>
    </inertial>
    <visual>
      <geometry>
        <mesh filename="package://cet200_description/meshes/roller.dae"/>
      </geometry>
    </visual>
    <collision>
      <origin rpy="1.5708 0 0" xyz="0 0 0"/>
      <geometry>
        <cylinder length="0.2144" radius="0.048"/>
      </geometry>
    </collision>
  </link>
  <joint name="Hinge_Roller_L7" type="continuous">
    <origin rpy="0 0 0" xyz="-0.375 1.1 0.18295"/>
    <axis xyz="0 1 0"/>
    <parent link="RB_TrackFrame"/>
    <child link="RB_Roller_L7"/>
  </joint>
  <link name="RB_Roller_L7">
    <inertial>
      <mass value="35"/>
      <origin rpy="0 0 0" xyz="0 0 0"/>
      <inertia ixx="0.181184" ixy="4.37227e-07" ixz="3.54717e-07" iyy="0.1057" iyz="0.0612396" izz="0.131501"/>
    </inertial>
    <visual>
      <geometry>
        <mesh filename="package://cet200_description/meshes/roller.dae"/>
      </geometry>
    </visual>
    <collision>
      <origin rpy="1.5708 0 0" xyz="0 0 0"/>
      <geometry>
        <cylinder length="0.2144" radius="0.048"/>
      </geometry>
    </collision>
  </link>
  <joint name="Hinge_Roller_L8" type="continuous">
    <origin rpy="0 0 0" xyz="-0.775 1.1 0.18295"/>
    <axis xyz="0 1 0"/>
    <parent link="RB_TrackFrame"/>
    <child link="RB_Roller_L8"/>
  </joint>
  <link name="RB_Roller_L8">
    <inertial>
      <mass value="35"/>
      <origin rpy="0 0 0" xyz="0 0 0"/>
      <inertia ixx="0.181184" ixy="4.37227e-07" ixz="3.54717e-07" iyy="0.1057" iyz="0.0612396" izz="0.131501"/>
    </inertial>
    <visual>
      <geometry>
        <mesh filename="package://cet200_description/meshes/roller.dae"/>
      </geometry>
    </visual>
    <collision>
      <origin rpy="1.5708 0 0" xyz="0 0 0"/>
      <geometry>
        <cylinder length="0.2144" radius="0.048"/>
      </geometry>
    </collision>
  </link>
  <joint name="Hinge_Roller_L9" type="continuous">
    <origin rpy="0 0 0" xyz="-1.175 1.1 0.18295"/>
    <axis xyz="0 1 0"/>
    <parent link="RB_TrackFrame"/>
    <child link="RB_Roller_L9"/>
  </joint>
  <link name="RB_Roller_L9">
    <inertial>
      <mass value="35"/>
      <origin rpy="0 0 0" xyz="0 0 0"/>
      <inertia ixx="0.181184" ixy="4.37227e-07" ixz="3.54717e-07" iyy="0.1057" iyz="0.0612396" izz="0.131501"/>
    </inertial>
    <visual>
      <geometry>
        <mesh filename="package://cet200_description/meshes/roller.dae"/>
      </geometry>
    </visual>
    <collision>
      <origin rpy="1.5708 0 0" xyz="0 0 0"/>
      <geometry>
        <cylinder length="0.2144" radius="0.048"/>
      </geometry>
    </collision>
  </link>
  <joint name="Hinge_Sprocket_R" type="continuous">
    <origin rpy="0 0 0" xyz="-1.6872 -1.1 0.38945"/>
    <axis xyz="0 1 0"/>
    <parent link="RB_TrackFrame"/>
    <child link="RB_Sprocket_R"/>
    <limit effort="38437" velocity="4.074104494"/>
  </joint>
  <link name="RB_Sprocket_R">
    <inertial>
      <mass value="340"/>
      <origin rpy="0 0 0" xyz="0.0009721884578390849 0.06961311938672243 -0.00024814935669242866"/>
      <inertia ixx="10.2047" ixy="-0.459781" ixz="2.23037e-10" iyy="6.83585" iyz="-2.9895e-11" izz="6.77422"/>
    </inertial>
    <visual>
      <origin rpy="3.141592653589793 0.0305 0" xyz="0 0 0"/>
      <geometry>
        <mesh filename="package://cet200_description/meshes/sprocket.dae"/>
      </geometry>
    </visual>
    <collision>
      <origin rpy="1.5708 0 0" xyz="0 0 0"/>
      <geometry>
        <cylinder length="0.05" radius="0.24"/>
      </geometry>
    </collision>
  </link>
  <joint name="Hinge_Idler_R" type="continuous">
    <origin rpy="0 0 0" xyz="1.6872 -1.1 0.38945"/>
    <axis xyz="0 1 0"/>
    <parent link="RB_TrackFrame"/>
    <child link="RB_Idler_R"/>
  </joint>
  <link name="RB_Idler_R">
    <inertial>
      <mass value="108"/>
      <origin rpy="0 0 0" xyz="0 0 0"/>
      <inertia ixx="2.34497" ixy="0" ixz="0" iyy="4.27217" iyz="4.22502e-06" izz="2.345"/>
    </inertial>
    <visual>
      <geometry>
        <mesh filename="package://cet200_description/meshes/idler.dae"/>
      </geometry>
    </visual>
    <collision>
      <origin rpy="1.5708 0 0" xyz="0 0 0"/>
      <geometry>
        <cylinder length="0.14" radius="0.24"/>
      </geometry>
    </collision>
  </link>
  <joint name="Hinge_Roller_R1" type="continuous">
    <origin rpy="0 0 0" xyz="0.55 -1.1 0.71245"/>
    <axis xyz="0 1 0"/>
    <parent link="RB_TrackFrame"/>
    <child link="RB_Roller_R1"/>
  </joint>
  <link name="RB_Roller_R1">
    <inertial>
      <mass value="35"/>
      <origin rpy="0 0 0" xyz="0 0 0"/>
      <inertia ixx="0.181184" ixy="4.37227e-07" ixz="3.54717e-07" iyy="0.1057" iyz="0.0612396" izz="0.131501"/>
    </inertial>
    <visual>
      <geometry>
        <mesh filename="package://cet200_description/meshes/roller.dae"/>
      </geometry>
    </visual>
    <collision>
      <origin rpy="1.5708 0 0" xyz="0 0 0"/>
      <geometry>
        <cylinder length="0.2144" radius="0.048"/>
      </geometry>
    </collision>
  </link>
  <joint name="Hinge_Roller_R2" type="continuous">
    <origin rpy="0 0 0" xyz="-0.55 -1.1 0.71245"/>
    <axis xyz="0 1 0"/>
    <parent link="RB_TrackFrame"/>
    <child link="RB_Roller_R2"/>
  </joint>
  <link name="RB_Roller_R2">
    <inertial>
      <mass value="35"/>
      <origin rpy="0 0 0" xyz="0 0 0"/>
      <inertia ixx="0.181184" ixy="4.37227e-07" ixz="3.54717e-07" iyy="0.1057" iyz="0.0612396" izz="0.131501"/>
    </inertial>
    <visual>
      <geometry>
        <mesh filename="package://cet200_description/meshes/roller.dae"/>
      </geometry>
    </visual>
    <collision>
      <origin rpy="1.5708 0 0" xyz="0 0 0"/>
      <geometry>
        <cylinder length="0.2144" radius="0.048"/>
      </geometry>
    </collision>
  </link>
  <joint name="Hinge_Roller_R3" type="continuous">
    <origin rpy="0 0 0" xyz="1.225 -1.1 0.18295"/>
    <axis xyz="0 1 0"/>
    <parent link="RB_TrackFrame"/>
    <child link="RB_Roller_R3"/>
  </joint>
  <link name="RB_Roller_R3">
    <inertial>
      <mass value="35"/>
      <origin rpy="0 0 0" xyz="0 0 0"/>
      <inertia ixx="0.181184" ixy="4.37227e-07" ixz="3.54717e-07" iyy="0.1057" iyz="0.0612396" izz="0.131501"/>
    </inertial>
    <visual>
      <geometry>
        <mesh filename="package://cet200_description/meshes/roller.dae"/>
      </geometry>
    </visual>
    <collision>
      <origin rpy="1.5708 0 0" xyz="0 0 0"/>
      <geometry>
        <cylinder length="0.2144" radius="0.048"/>
      </geometry>
    </collision>
  </link>
  <joint name="Hinge_Roller_R4" type="continuous">
    <origin rpy="0 0 0" xyz="0.825 -1.1 0.18295"/>
    <axis xyz="0 1 0"/>
    <parent link="RB_TrackFrame"/>
    <child link="RB_Roller_R4"/>
  </joint>
  <link name="RB_Roller_R4">
    <inertial>
      <mass value="35"/>
      <origin rpy="0 0 0" xyz="0 0 0"/>
      <inertia ixx="0.181184" ixy="4.37227e-07" ixz="3.54717e-07" iyy="0.1057" iyz="0.0612396" izz="0.131501"/>
    </inertial>
    <visual>
      <geometry>
        <mesh filename="package://cet200_description/meshes/roller.dae"/>
      </geometry>
    </visual>
    <collision>
      <origin rpy="1.5708 0 0" xyz="0 0 0"/>
      <geometry>
        <cylinder length="0.2144" radius="0.048"/>
      </geometry>
    </collision>
  </link>
  <joint name="Hinge_Roller_R5" type="continuous">
    <origin rpy="0 0 0" xyz="0.425 -1.1 0.18295"/>
    <axis xyz="0 1 0"/>
    <parent link="RB_TrackFrame"/>
    <child link="RB_Roller_R5"/>
  </joint>
  <link name="RB_Roller_R5">
    <inertial>
      <mass value="35"/>
      <origin rpy="0 0 0" xyz="0 0 0"/>
      <inertia ixx="0.181184" ixy="4.37227e-07" ixz="3.54717e-07" iyy="0.1057" iyz="0.0612396" izz="0.131501"/>
    </inertial>
    <visual>
      <geometry>
        <mesh filename="package://cet200_description/meshes/roller.dae"/>
      </geometry>
    </visual>
    <collision>
      <origin rpy="1.5708 0 0" xyz="0 0 0"/>
      <geometry>
        <cylinder length="0.2144" radius="0.048"/>
      </geometry>
    </collision>
  </link>
  <joint name="Hinge_Roller_R6" type="continuous">
    <origin rpy="0 0 0" xyz="0.025 -1.1 0.18295"/>
    <axis xyz="0 1 0"/>
    <parent link="RB_TrackFrame"/>
    <child link="RB_Roller_R6"/>
  </joint>
  <link name="RB_Roller_R6">
    <inertial>
      <mass value="35"/>
      <origin rpy="0 0 0" xyz="0 0 0"/>
      <inertia ixx="0.181184" ixy="4.37227e-07" ixz="3.54717e-07" iyy="0.1057" iyz="0.0612396" izz="0.131501"/>
    </inertial>
    <visual>
      <geometry>
        <mesh filename="package://cet200_description/meshes/roller.dae"/>
      </geometry>
    </visual>
    <collision>
      <origin rpy="1.5708 0 0" xyz="0 0 0"/>
      <geometry>
        <cylinder length="0.2144" radius="0.048"/>
      </geometry>
    </collision>
  </link>
  <joint name="Hinge_Roller_R7" type="continuous">
    <origin rpy="0 0 0" xyz="-0.375 -1.1 0.18295"/>
    <axis xyz="0 1 0"/>
    <parent link="RB_TrackFrame"/>
    <child link="RB_Roller_R7"/>
  </joint>
  <link name="RB_Roller_R7">
    <inertial>
      <mass value="35"/>
      <origin rpy="0 0 0" xyz="0 0 0"/>
      <inertia ixx="0.181184" ixy="4.37227e-07" ixz="3.54717e-07" iyy="0.1057" iyz="0.0612396" izz="0.131501"/>
    </inertial>
    <visual>
      <geometry>
        <mesh filename="package://cet200_description/meshes/roller.dae"/>
      </geometry>
    </visual>
    <collision>
      <origin rpy="1.5708 0 0" xyz="0 0 0"/>
      <geometry>
        <cylinder length="0.2144" radius="0.048"/>
      </geometry>
    </collision>
  </link>
  <joint name="Hinge_Roller_R8" type="continuous">
    <origin rpy="0 0 0" xyz="-0.775 -1.1 0.18295"/>
    <axis xyz="0 1 0"/>
    <parent link="RB_TrackFrame"/>
    <child link="RB_Roller_R8"/>
  </joint>
  <link name="RB_Roller_R8">
    <inertial>
      <mass value="35"/>
      <origin rpy="0 0 0" xyz="0 0 0"/>
      <inertia ixx="0.181184" ixy="4.37227e-07" ixz="3.54717e-07" iyy="0.1057" iyz="0.0612396" izz="0.131501"/>
    </inertial>
    <visual>
      <geometry>
        <mesh filename="package://cet200_description/meshes/roller.dae"/>
      </geometry>
    </visual>
    <collision>
      <origin rpy="1.5708 0 0" xyz="0 0 0"/>
      <geometry>
        <cylinder length="0.2144" radius="0.048"/>
      </geometry>
    </collision>
  </link>
  <joint name="Hinge_Roller_R9" type="continuous">
    <origin rpy="0 0 0" xyz="-1.175 -1.1 0.18295"/>
    <axis xyz="0 1 0"/>
    <parent link="RB_TrackFrame"/>
    <child link="RB_Roller_R9"/>
  </joint>
  <link name="RB_Roller_R9">
    <inertial>
      <mass value="35"/>
      <origin rpy="0 0 0" xyz="0 0 0"/>
      <inertia ixx="0.181184" ixy="4.37227e-07" ixz="3.54717e-07" iyy="0.1057" iyz="0.0612396" izz="0.131501"/>
    </inertial>
    <visual>
      <geometry>
        <mesh filename="package://cet200_description/meshes/roller.dae"/>
      </geometry>
    </visual>
    <collision>
      <origin rpy="1.5708 0 0" xyz="0 0 0"/>
      <geometry>
        <cylinder length="0.2144" radius="0.048"/>
      </geometry>
    </collision>
  </link>
  <joint name="Dummy_LockJoint_CrawlerBelt_L" type="fixed">
    <origin rpy="0 0 0" xyz="1.6872 1.09461 0.38945"/>
    <parent link="RB_TrackFrame"/>
    <child link="Dummy_RB_CrawlerBelt_L"/>
  </joint>
  <link name="Dummy_RB_CrawlerBelt_L">
    <visual>
      <geometry>
        <mesh filename="package://cet200_description/meshes/crawler_belt.dae"/>
      </geometry>
    </visual>
  </link>
  <joint name="Dummy_LockJoint_CrawlerBelt_R" type="fixed">
    <origin rpy="0 0 0" xyz="1.6872 -1.09461 0.38945"/>
    <parent link="RB_TrackFrame"/>
    <child link="Dummy_RB_CrawlerBelt_R"/>
  </joint>
  <link name="Dummy_RB_CrawlerBelt_R">
    <visual>
      <geometry>
        <mesh filename="package://cet200_description/meshes/crawler_belt.dae"/>
      </geometry>
    </visual>
  </link>
  <!-- Attachments -->
  <!-- TF_LidarBase -->
  <joint name="Dummy_LockJoint_RB_UpperStructure_RB_LidarBase" type="fixed">
    <parent link="RB_UpperStructure"/>
    <child link="TF_LidarBase"/>
    <origin rpy="0 0.7853981633974483 0" xyz="1.17928 0.9 2.10413"/>
    <axis xyz="0 1 0"/>
  </joint>
  <link name="TF_LidarBase"/>
</robot>
